2020-01-17 18:00:08.124 | INFO     | __main__:<module>:21 - xxxx
2020-01-17 18:00:08.126 | INFO     | __main__:<module>:23 - this is a info message
2020-01-17 18:00:08.126 | ERROR    | __main__:<module>:33 - An error has been caught in function '<module>', process 'MainProcess' (6230), thread 'MainThread' (140734929661376):
Traceback (most recent call last):

> File "/Users/yuanjie/Desktop/Projects/Python/tql-App/iapp/log/__init__.py", line 33, in <module>
    print(f())
          â”” <function f at 0x115d1a6a8>

  File "/Users/yuanjie/Desktop/Projects/Python/tql-App/iapp/log/__init__.py", line 29, in f
    1 / 0

ZeroDivisionError: division by zero
